Workbook

Sheet Links
A1: group | B1: kind | C1: name | D1: code | E1: unit | F1: unit_price | G1: current_balance | H1: adjustment_coefficient | I1: Type 1 | J1: Type 2 | K1: Type 3 | L1: Type 4 | M1: Formula 1 | N1: Formula 2 | O1: Formula 3 | P1: Formula 4
A2: pavement | B2: 1 | C2: TAPA BURACO COM SERRA CORTA-PISO | D2: 1 | E2: m³ | F2: 300 | G2: 10000 | H2: 1.15 | I2: Tapa Buraco | M2: {"backend": {"*": [{"var": "formData.width"}, {"var": "formData.length"}, {"var": "formData.height"}]}}
A3: pavement | B3: 1 | C3: AQUISIÇÃO DE CAP-50/70 TRANSPORTE DE CAP-50/70 | D3: 2 | E3: m³ | F3: 100 | G3: 10000 | H3: 1.1 | I3: Tapa Buraco | J3: Remendo profundo | K3: Fresagem e recomposição | L3: Microrrevestimento | M3: {"backend": {"*": [{"var": "formData.width"}, {"var": "formData.length"}, {"var": "formData.height"}]}} | N3: {"backend": {"*": [{"var": "formData.width"}, {"var": "formData.length"}, {"var": "formData.height"}]}} | O3: {"backend": {"*": [{"var": "formData.width"}, {"var": "formData.length"}, {"var": "formData.height"}]}} | P3: {"backend": {"*": [{"var": "formData.width"}, {"var": "formData.length"}, {"var": "formData.height"}]}}
A4: pavement | B4: 1 | C4: DEMOLIÇÃO MECÂNICA | D4: 3 | E4: m³ | F4: 100 | G4: 10000 | H4: 1.2 | I4: Remendo profundo | J4: Fresagem e recomposição | M4: {"backend": {"*": [{"var": "formData.width"}, {"var": "formData.length"}, {"var": "formData.height"}]}} | N4: {"backend": {"*": [{"var": "formData.width"}, {"var": "formData.length"}, {"var": "formData.height"}]}}
A5: pavement | B5: 1 | C5: MISTURA BETUMINOSA USINADA A QUENTE | D5: 4 | E5: m³ | F5: 600 | G5: 10000 | H5: 1.3 | I5: Tapa Buraco | J5: Remendo profundo | K5: Fresagem e recomposição | L5: Microrrevestimento | M5: {"backend": {"*": [{"var": "formData.width"}, {"var": "formData.length"}, {"var": "formData.height"}]}} | N5: {"backend": {"*": [{"var": "formData.width"}, {"var": "formData.length"}, {"var": "formData.height"}]}} | O5: {"backend": {"*": [{"var": "formData.width"}, {"var": "formData.length"}, {"var": "formData.height"}]}} | P5: {"backend": {"*": [{"var": "formData.width"}, {"var": "formData.length"}, {"var": "formData.height"}]}}
A6: pavement | B6: 1 | C6: BRITA PARA BASE | D6: 5 | E6: m³ | F6: 40 | G6: 10000 | H6: 1.2 | I6: Remendo profundo | J6: Fresagem e recomposição | M6: {"backend": {"*": [{"var": "formData.width"}, {"var": "formData.length"}, {"var": "formData.height"}]}} | N6: {"backend": {"*": [{"var": "formData.width"}, {"var": "formData.length"}, {"var": "formData.height"}]}}
A7: other_services | B7: 2 | C7: ASSENTAMENTO DE DRENO PROFUNDO | D7: 6 | E7: m | F7: 100 | G7: 10000 | H7: 1.1 | I7: Dreno Longitudinal 15x60 | J7: Dreno Transversal 13x30 | M7: {"backend": {"var": "formData.length"}} | N7: {"backend": {"var": "formData.length"}}
A8: other_services | B8: 2 | C8: INSTALAÇÃO DE CERCA 4 FIOS | D8: 7 | E8: m | F8: 50 | G8: 10000 | H8: 1.5 | I8: Cerca 4 Fios | M8: {"backend": {"var": "formData.length"}}
A9: signaling | B9: 3 | C9: PINTURA DE FAIXA – TINTA BASE ACRÍLICA P/ 1 ANO | D9: 8 | E9: m | F9: 100 | G9: 10000 | H9: 1.2 | I9: Faixa de sinalização Definitiva | M9: {"backend": {"var": "formData.length"}}
A10: signaling | B10: 3 | C10: INSTALAÇÃO DE TACHÃO REFLEXIVO | D10: 9 | E10: m | F10: 120 | G10: 10000 | H10: 1.4 | I10: Tachão refletivo bidirecional | M10: {"backend": {"var": "formData.length"}}
A11: signaling | B11: 3 | C11: LIMPEZA DE PLACA | D11: 10 | E11: m | F11: 70 | G11: 10000 | H11: 1.4 | I11: Limpeza de Placa | M11: {"backend": {"var": "formData.length"}}

Sheet Alteração Ind Reaj
A1: Serviço | B1: Coef. Ajuste Bocaína | C1: Coef Aj. RL | D1: Delta
A2: AQUISIÇÃO DE CAP-50/70 | B2: 0.442 | C2: =VLOOKUP(A2,Links!$C$2:$H$10,6,FALSE) -> #N/A | D2: =ABS(C2-1-B2) -> #N/A
A3: MISTURA BETUMINOSA USINADA A QUENTE AC/BC | B3: 0.107 | C3: =VLOOKUP(A3,Links!$C$2:$H$10,6,FALSE) -> #N/A | D3: =ABS(C3-1-B3) -> #N/A
A4: TAPA BURACO COM SERRA CORTA-PISO | B4: 0.0728 | C4: =VLOOKUP(A4,Links!$C$2:$H$10,6,FALSE) -> 1.15 | D4: =ABS(C4-1-B4) -> 0.0772
A5: AQUISIÇAO RR-1C P/ TAPA BURACO | B5: 0.3898 | C5: =VLOOKUP(A5,Links!$C$2:$H$10,6,FALSE) -> #N/A | D5: =ABS(C5-1-B5) -> #N/A
A6: TRANSPORTE DE RR-1C P/ TAPA BURACO | B6: 0.107 | C6: =VLOOKUP(A6,Links!$C$2:$H$10,6,FALSE) -> #N/A | D6: =ABS(C6-1-B6) -> #N/A
A7: TRANSPORTE DE CAP-50/70 | B7: 0.107 | C7: =VLOOKUP(A7,Links!$C$2:$H$10,6,FALSE) -> #N/A | D7: =ABS(C7-1-B7) -> #N/A
C8: =VLOOKUP(A8,Links!$C$2:$H$10,6,FALSE) -> #N/A | D8: =ABS(C8-1-B8) -> #N/A
A9: AQUISIÇÃO DE CAP-50/70 | B9: 0.442 | C9: =VLOOKUP(A9,Links!$C$2:$H$10,6,FALSE) -> #N/A | D9: =ABS(C9-1-B9) -> #N/A
A10: REMENDO PROFUNDO COM DEMOLIÇÃO MECÂNICA E SERRA | B10: 0.0728 | C10: =VLOOKUP(A10,Links!$C$2:$H$10,6,FALSE) -> #N/A | D10: =ABS(C10-1-B10) -> #N/A | E10: =B10+1 -> 1.0728
A11: MISTURA BETUMINOSA USINADA A QUENTE AC/BC | B11: 0.107 | C11: =VLOOKUP(A11,Links!$C$2:$H$10,6,FALSE) -> #N/A | D11: =ABS(C11-1-B11) -> #N/A
A12: AQUISIÇÃO DE CM-30 PARA IMPRIMAÇÃO | B12: 0.4841 | C12: =VLOOKUP(A12,Links!$C$2:$H$10,6,FALSE) -> #N/A | D12: =ABS(C12-1-B12) -> #N/A | E12: =B12+1 -> 1.4841
A13: TRANSPORTE DE CM-30 P/ IMPRIMAÇÃO | B13: 0.107 | C13: =VLOOKUP(A13,Links!$C$2:$H$10,6,FALSE) -> #N/A | D13: =ABS(C13-1-B13) -> #N/A
A14: TRANSPORTE DE CAP-50/70 | B14: 0.107 | C14: =VLOOKUP(A14,Links!$C$2:$H$10,6,FALSE) -> #N/A | D14: =ABS(C14-1-B14) -> #N/A
A15: BRITA PARA BASE DE REMENDO PROFUNDO | B15: 0.107 | C15: =VLOOKUP(A15,Links!$C$2:$H$10,6,FALSE) -> #N/A | D15: =ABS(C15-1-B15) -> #N/A | E15: =B15+1 -> 1.107
A16: IMPRIMAÇÃO | B16: 0.107 | C16: =VLOOKUP(A16,Links!$C$2:$H$10,6,FALSE) -> #N/A | D16: =ABS(C16-1-B16) -> #N/A
C17: =VLOOKUP(A17,Links!$C$2:$H$10,6,FALSE) -> #N/A | D17: =ABS(C17-1-B17) -> #N/A
A18: RECOMPOSIÇÃO DE GUARDA-CORPO AC/BC | B18: 0.0728 | C18: =VLOOKUP(A18,Links!$C$2:$H$10,6,FALSE) -> #N/A | D18: =ABS(C18-1-B18) -> #N/A
A19: RESTAURAÇÃO DE DISP. DANIF. COM CONCRETO FCK= 15MPa AC/BC | C19: =VLOOKUP(A19,Links!$C$2:$H$10,6,FALSE) -> #N/A | D19: =ABS(C19-1-B19) -> #N/A
A20: ALVENARIA DE TIJOLOS 20 cm ESPESSURA AC | C20: =VLOOKUP(A20,Links!$C$2:$H$10,6,FALSE) -> #N/A | D20: =ABS(C20-1-B20) -> #N/A
A21: RECOMPOSIÇÃO PARCIAL CERCA MOURÃO CONC. SEÇÃO QUADR. AC/BC | C21: =VLOOKUP(A21,Links!$C$2:$H$10,6,FALSE) -> #N/A | D21: =ABS(C21-1-B21) -> #N/A
A22: RECOMPOSIÇÃO TOTAL CERCA C/ SUP. CONC. SEÇÃO QUADR. AC/BC | B22: 0.0728 | C22: =VLOOKUP(A22,Links!$C$2:$H$10,6,FALSE) -> #N/A | D22: =ABS(C22-1-B22) -> #N/A
A23: DESM.DEST.E LIMP.AREAS ARV. D ATE 0,15M | C23: =VLOOKUP(A23,Links!$C$2:$H$10,6,FALSE) -> #N/A | D23: =ABS(C23-1-B23) -> #N/A
A24: DESTOCAMENTO DE ÁRVORES D=0,15 A 0,30 M | C24: =VLOOKUP(A24,Links!$C$2:$H$10,6,FALSE) -> #N/A | D24: =ABS(C24-1-B24) -> #N/A
A25: CONCRETO DE CIMENTO (CONFECÇÃO E LANÇAM.) AC/BC | B25: 0.1333 | C25: =VLOOKUP(A25,Links!$C$2:$H$10,6,FALSE) -> #N/A | D25: =ABS(C25-1-B25) -> #N/A
A26: REGULARIZAÇÃO MECÂNICA DA FAIXA DE DOMÍNIO | B26: 0.1277 | C26: =VLOOKUP(A26,Links!$C$2:$H$10,6,FALSE) -> #N/A | D26: =ABS(C26-1-B26) -> #N/A
A27: REATERRO APILOADO | B27: 0.1277 | C27: =VLOOKUP(A27,Links!$C$2:$H$10,6,FALSE) -> #N/A | D27: =ABS(C27-1-B27) -> #N/A
A28: ASSENTAMENTO DE TUBO D=0,60M AC/BC | B28: 0.0728 | C28: =VLOOKUP(A28,Links!$C$2:$H$10,6,FALSE) -> #N/A | D28: =ABS(C28-1-B28) -> #N/A
A29: ASSENTAMENTO DE TUBO D=0,80M AC/BC | B29: 0.0728 | C29: =VLOOKUP(A29,Links!$C$2:$H$10,6,FALSE) -> #N/A | D29: =ABS(C29-1-B29) -> #N/A
A30: REATERRO E COMPACTAÇÃO P/ BUEIRO | B30: 0.1277 | C30: =VLOOKUP(A30,Links!$C$2:$H$10,6,FALSE) -> #N/A | D30: =ABS(C30-1-B30) -> #N/A | E30: =B30+1 -> 1.1277
A31: ENROCAMENTO DE PEDRA JOGADA | B31: 0.1277 | C31: =VLOOKUP(A31,Links!$C$2:$H$10,6,FALSE) -> #N/A | D31: =ABS(C31-1-B31) -> #N/A | E31: =B31+1 -> 1.1277
A32: CONCRETO CICLÓPICO AC/BC/PC | B32: 0.1333 | C32: =VLOOKUP(A32,Links!$C$2:$H$10,6,FALSE) -> #N/A | D32: =ABS(C32-1-B32) -> #N/A
A33: FORNECIMENTO PREP. COLOCAÇÃO AÇO CA-50 | B33: 0.1333 | C33: =VLOOKUP(A33,Links!$C$2:$H$10,6,FALSE) -> #N/A | D33: =ABS(C33-1-B33) -> #N/A | E33: =B33+1 -> 1.1333
A34: FORMA COMUM DE MADEIRA | B34: 0.1333 | C34: =VLOOKUP(A34,Links!$C$2:$H$10,6,FALSE) -> #N/A | D34: =ABS(C34-1-B34) -> #N/A
A35: LIMPEZA DE PONTE | B35: 0.0728 | C35: =VLOOKUP(A35,Links!$C$2:$H$10,6,FALSE) -> #N/A | D35: =ABS(C35-1-B35) -> #N/A
A36: ESCAVAÇÃO MANUAL EM MATERIAL DE 1ª CAT. | B36: 0.1277 | C36: =VLOOKUP(A36,Links!$C$2:$H$10,6,FALSE) -> #N/A | D36: =ABS(C36-1-B36) -> #N/A
A37: ESCAVAÇÃO MECANIZADA DE VALA EM MATERIAL DE 1ª CAT. | B37: 0.1277 | C37: =VLOOKUP(A37,Links!$C$2:$H$10,6,FALSE) -> #N/A | D37: =ABS(C37-1-B37) -> #N/A
A38: DRENO SUB-HORIZONTAL - DSH 01 | C38: =VLOOKUP(A38,Links!$C$2:$H$10,6,FALSE) -> #N/A | D38: =ABS(C38-1-B38) -> #N/A
A39: BOCA SAÍDA DRENO SUB-HORIZONTAL BSD-04 | C39: =VLOOKUP(A39,Links!$C$2:$H$10,6,FALSE) -> #N/A | D39: =ABS(C39-1-B39) -> #N/A
A40: PERFURAÇÃO P/ DRENO SUB-HORIZ. MAT 1°CAT | C40: =VLOOKUP(A40,Links!$C$2:$H$10,6,FALSE) -> #N/A | D40: =ABS(C40-1-B40) -> #N/A
...
